Workbook

Sheet Dados
A1: id_registro | B1: placa | C1: data_hora_chegada | D1: quilometragem | E1: responsavel | F1: servico | G1: status | H1: data_hora_inicio_manutencao | I1: data_hora_termino | J1: data_hora_liberacao
A2: 1001 | B2: BGU2B80 | C2: 01/07/2026 08:51 | D2: 74432 | E2: Marcos Vinícius Lima | F2: Alinhamento e balanceamento | G2: Liberado | I2: 01/07/2026 13:27 | J2: 01/07/2026 14:42
A3: 1002 | B3: NTK7931 | C3: 02/07/2026 12:24 | D3: 119892 | E3: marcos vinícius lima | F3: Reparo elétrico | G3: Liberado | I3: 02/07/2026 21:43 | J3: 02/07/2026 22:20
A4: 1003 | B4: ZQE2264 | C4: 02/07/2026 13:17 | D4: 122243 | E4: Rafael Moreira | F4: Troca de óleo | G4: Liberado | H4: 02/07/2026 16:31 | I4: 02/07/2026 17:17 | J4: 02/07/2026 17:50
A5: 1004 | B5: RMV4R87 | C5: 02/07/2026 13:25 | D5: 130138 | E5: Ana Paula Ribeiro | F5: Alinhamento e balanceamento | G5: Liberado | I5: 02/07/2026 15:35 | J5: 02/07/2026 18:08
A6: 1005 | B6: AWL5O61 | C6: 2026-07-02 17:11 | D6: 34836 | E6: Rafael Moreira | F6: Revisão preventiva | G6: Liberado | H6: 02/07/2026 18:20 | I6: 02/07/2026 21:22 | J6: 03/07/2026 00:22
A7: 1006 | B7: RRJ4729 | C7: 03/07/2026 08:20 | D7: 148160 | E7: Juliana Castro | F7: Troca de correia dentada | G7: Liberado | I7: 03/07/2026 17:05 | J7: 03/07/2026 20:49
A8: 1007 | B8: HAJ1189 | C8: 04/07/2026 06:53 | D8: 106727 | E8: Marcos Vinícius Lima | F8: Troca de óleo | G8: Liberado | H8: 04/07/2026 11:28 | I8: 04/07/2026 12:31 | J8: 04/07/2026 16:15
A9: 1008 | B9: KTG9O61 | C9: 04/07/2026 13:02 | D9: 180321 | E9: Sandra Nogueira | F9: Troca de óleo | G9: Liberado | H9: 04/07/2026 18:53 | I9: 04/07/2026 19:30 | J9: 04/07/2026 21:58
A10: 1009 | B10: KTG9O61 | C10: 04/07/2026 13:02 | D10: 180321 | E10: Sandra Nogueira | F10: Troca de óleo | G10: Liberado | H10: 04/07/2026 18:53 | I10: 04/07/2026 19:30 | J10: 04/07/2026 21:58
A11: 1010 | B11: ATC1417 | C11: 05/07/2026 10:23 | D11: 32345 | E11: Fernanda Alves | F11: TROCA DE PNEUS | G11: Liberado | H11: 05/07/2026 17:29 | I11: 05/07/2026 19:10 | J11: 05/07/2026 20:08
A12: 1011 | B12: YUG7W02 | C12: 05/07/2026 10:44 | D12: 163526 | E12: Luciana Prado | F12: Troca de pneus | G12: Liberado | H12: 05/07/2026 11:53 | I12: 05/07/2026 13:31 | J12: 05/07/2026 16:42
A13: 1012 | B13: KSA8K38 | C13: 06/07/2026 11:05 | D13: 143356 | E13: Carlos Mendes | F13: Troca de óleo | G13: Liberado | H13: 06/07/2026 16:33 | I13: 06/07/2026 17:58 | J13: 06/07/2026 21:35
A14: 1013 | B14: ZSR7Y97 | C14: 06/07/2026 11:43 | E14: Eduardo Pinto | F14: Troca de pneus | G14: Liberado | H14: 06/07/2026 12:34 | I14: 06/07/2026 14:02 | J14: 06/07/2026 17:55
A15: 1014 | B15: NFD0521 | C15: 07/07/2026 08:25 | D15: 167296 | E15: Ricardo Teixeira | F15: Troca de óleo | G15: Liberado | H15: 07/07/2026 09:01 | I15: 07/07/2026 09:31 | J15: 07/07/2026 11:26
A16: 1015 | B16: ISC4K24 | C16: 07/07/2026 13:16 | D16: 74893 | E16: Juliana Castro | F16: Alinhamento e balanceamento | G16: Liberado | H16: 07/07/2026 15:43 | I16: 07/07/2026 17:10 | J16: 07/07/2026 17:47
A17: 1016 | B17: XDF9110 | C17: 07/07/2026 14:43 | E17: Ana Paula Ribeiro | F17: Alinhamento e balanceamento | G17: Liberado | H17: 07/07/2026 18:00 | I17: 07/07/2026 19:34 | J17: 07/07/2026 23:15
A18: 1017 | B18: kvj7k17 | C18: 08/07/2026 12:16 | D18: 25325 | E18: Paulo Henrique Dias | F18: Revisão preventiva | G18: Liberado | H18: 08/07/2026 18:05 | I18: 08/07/2026 22:41 | J18: 09/07/2026 00:37
A19: 1018 | B19: DTW4893 | C19: 11/07/2026 12:08 | D19: 159171 | E19: Sandra Nogueira | F19: Troca de óleo | G19: Liberado | H19: 11/07/2026 16:02 | I19: 11/07/2026 16:34 | J19: 11/07/2026 17:31
A20: 1019 | B20: QYP6R04 | C20: 11/07/2026 12:19 | D20: 123869 | E20: Ricardo Teixeira | F20: REPARO DE FREIOS | G20: Liberado | H20: 11/07/2026 18:18 | I20: 11/07/2026 20:36 | J20: 11/07/2026 21:27
A21: 1020 | B21: AOS8193 | C21: 12/07/2026 16:09 | D21: -133994 | E21: João Batista Souza | F21: Alinhamento e balanceamento | G21: Liberado | I21: 12/07/2026 21:30 | J21: 12/07/2026 21:54
A22: 1021 | B22: VPV-5364 | C22: 13/07/2026 10:53 | D22: 129204 | E22: Paulo Henrique Dias | F22: Troca de óleo | G22: Liberado | H22: 13/07/2026 18:09 | I22: 13/07/2026 18:59 | J22: 13/07/2026 21:37
A23: 1022 | B23: SIV8E14 | C23: 13/07/2026 15:54 | D23: 109789 | E23: Fernanda Alves | F23: Troca de correia dentada | G23: Liberado | H23: 13/07/2026 19:58 | I23: 14/07/2026 02:14 | J23: 14/07/2026 04:17
A24: 1023 | B24: BGU2B80 | C24: 15/07/2026 13:40 | D24: 82510 | E24: Carlos Mendes | F24: Reparo de freios | G24: liberado | H24: 15/07/2026 14:59 | I24: 15/07/2026 18:23 | J24: 15/07/2026 20:53
A25: 1024 | B25: ALF5898 | C25: 16/07/2026 10:41 | D25: 54090 | E25: Marcos Vinícius Lima | F25: Troca de óleo | G25: Liberado | I25: 16/07/2026 13:49 | J25: 16/07/2026 16:54
A26: 1025 | B26: STZ2E98 | C26: 2026-07-16 10:54 | D26: 84363 | E26: João Batista Souza | F26: Reparo elétrico | G26: Liberado | H26: 16/07/2026 15:55 | I26: 16/07/2026 20:48 | J26: 16/07/2026 22:46
A27: 1026 | B27: DGX6E70 | C27: 16/07/2026 15:28 | D27: 107554 | E27: Fernanda Alves | F27: Troca de Oleo | G27: Liberado | H27: 16/07/2026 21:08 | I27: 16/07/2026 21:55 | J27: 16/07/2026 23:04
A28: 1027 | B28: cbl5y00 | C28: 17/07/2026 12:58 | D28: 80385 | E28: Marcos Vinícius Lima | F28: Alinhamento e balanceamento | G28: Liberado | H28: 17/07/2026 16:31 | I28: 17/07/2026 18:15 | J28: 17/07/2026 19:32
A29: 1028 | B29: ATC1417 | C29: 18/07/2026 07:40 | D29: 38237 | E29: Juliana Castro | F29: Troca de óleo | G29: Liberado | I29: 18/07/2026 12:38 | J29: 18/07/2026 13:00
A30: 1029 | B30: KSA8K38 | C30: 18/07/2026 09:31 | D30: 149800 | E30: Carlos Mendes | F30: Reparo de freios | G30: Liberado | H30: 18/07/2026 14:50 | I30: 18/07/2026 17:03 | J30: 18/07/2026 18:05
A31: 1030 | B31: QYP6R04 | C31: 19/07/2026 08:08 | D31: 128552 | E31: Ricardo Teixeira | F31: Troca de óleo | G31: Liberado | H31: 19/07/2026 14:50 | I31: 19/07/2026 16:00 | J31: 19/07/2026 02:08
A32: 1031 | B32: RRJ-4729 | C32: 19/07/2026 16:52 | D32: 153871 | E32: Juliana Castro | F32: Troca de bateria | G32: Liberado | H32: 19/07/2026 20:06 | I32: 19/07/2026 20:56 | J32: 19/07/2026 23:19
A33: 1032 | B33: rnc6j25 | C33: 20/07/2026 07:51 | D33: 68319 | E33: Eduardo Pinto | F33: Reparo de freios | G33: Liberado | H33: 20/07/2026 13:04 | I33: 20/07/2026 14:49 | J33: 20/07/2026 18:24
A34: 1033 | B34: KQQ1399 | C34: 21/07/2026 16:22 | D34: 68478 | E34: Paulo Henrique Dias | F34: Troca de correia dentada | G34: Liberado | H34: 21/07/2026 21:09 | I34: 22/07/2026 03:08 | J34: 22/07/2026 05:02
A35: 1034 | B35: KYO9U90 | C35: 22/07/2026 08:34 | D35: 158001 | E35: Carlos Mendes | F35: Troca de óleo | G35: Liberado | H35: 22/07/2026 16:28 | I35: 22/07/2026 17:05 | J35: 22/07/2026 19:26
A36: 1035 | B36: RMV4R87 | C36: 23/07/2026 06:45 | D36: 131989 | E36: Ana Paula Ribeiro | F36: Troca de pneus | G36: Liberado | I36: 23/07/2026 13:30 | J36: 23/07/2026 13:44
A37: 1036 | B37: KVJ7K17 | C37: 23/07/2026 09:02 | D37: 33028 | E37: Fernanda Alves | F37: TROCA DE ÓLEO | G37: Liberado | H37: 23/07/2026 10:23 | I37: 23/07/2026 11:35 | J37: 23/07/2026 15:23
A38: 1037 | B38: dtb8452 | C38: 25/07/2026 07:16 | D38: 92386 | E38: Paulo Henrique Dias | F38: Troca de pneus | G38: Liberado | H38: 25/07/2026 10:41 | I38: 25/07/2026 11:50 | J38: 25/07/2026 12:48
A39: 1038 | B39: PSE9841 | C39: 25/07/2026 10:24 | D39: 55265 | E39: Rafael Moreira | F39: Alinhamento e balanceamento | G39: Liberado | H39: 25/07/2026 14:59 | I39: 25/07/2026 16:59 | J39: 25/07/2026 18:04
A40: 1039 | B40: yug7w02 | C40: 26/07/2026 07:25 | D40: 166978 | E40: Luciana Prado | F40: Revisão preventiva | G40: Liberado | I40: 26/07/2026 10:27 | J40: 26/07/2026 11:24
...

Sheet Leia-me
A1: Planilha de origem SIMULADA para o ETL da Etapa 6
A3: Todos os dados desta planilha são FICTÍCIOS. Placas, nomes e datas foram gerados para testar o ETL e não representam registros reais da empresa parceira.
A4: A estrutura segue os requisitos do sistema: chegada (RF02), serviço (RF03), status (RF04), término (RF05) e liberação (RF06).
A5: Todas as colunas da aba Dados estão como texto, como chegariam de uma digitação manual. O ETL deve converter os tipos.
A6: Formato padrão de data e hora: DD/MM/AAAA HH:MM.
A7: Período dos atendimentos: 01/07/2026 a 21/10/2026. Data de referência da extração: 21/10/2026 08:00.
A8: A coluna data_hora_inicio_manutencao pode estar vazia, porque esse horário é opcional no sistema.
A10: Abas:
A11: Dados: a fonte que o ETL deve ler.
A12: Gabarito: lista dos problemas inseridos de propósito e o tratamento esperado. Serve para conferir o ETL. Não deve ser lido pelo ETL.
A13: Resumo: contagens esperadas para conferir a carga (linhas lidas, rejeitadas, descartadas e carregadas na fato).

Sheet Gabarito
A1: id_registro | B1: tipo_problema | C1: classe | D1: descricao | E1: tratamento_esperado
A2: 1002 | B2: RESPONSAVEL_VARIANTE | C2: CORRIGIR | D2: Nome do responsável com caixa ou espaços diferentes | E2: Padronizar caixa e espaços
A3: 1005 | B3: DATA_FORMATO_ISO | C3: CORRIGIR | D3: Chegada em formato AAAA-MM-DD em vez de DD/MM/AAAA | E3: Converter para o formato padrão de data e hora
A4: 1007 | B4: PLACA_ESPACOS | C4: CORRIGIR | D4: Placa com espaços no início ou no fim | E4: Remover espaços
A5: 1009 | B5: DUPLICADO | C5: DESCARTAR | D5: Registro digitado duas vezes (mesma placa, chegada e serviço) | E5: Manter uma ocorrência e descartar a outra
A6: 1010 | B6: SERVICO_VARIANTE | C6: CORRIGIR | D6: Serviço escrito de forma diferente do padrão | E6: Padronizar por tabela de de-para (minúsculas, sem acento e sem espaços extras)
A7: 1011 | B7: SERVICO_VARIANTE | C7: CORRIGIR | D7: Serviço escrito de forma diferente do padrão | E7: Padronizar por tabela de de-para (minúsculas, sem acento e sem espaços extras)
A8: 1013 | B8: KM_VAZIO | C8: CORRIGIR | D8: Quilometragem não informada | E8: Carregar como nulo
A9: 1016 | B9: KM_VAZIO | C9: CORRIGIR | D9: Quilometragem não informada | E9: Carregar como nulo
A10: 1017 | B10: PLACA_MINUSCULA | C10: CORRIGIR | D10: Placa digitada em minúsculas | E10: Converter para maiúsculas
A11: 1019 | B11: SERVICO_VARIANTE | C11: CORRIGIR | D11: Serviço escrito de forma diferente do padrão | E11: Padronizar por tabela de de-para (minúsculas, sem acento e sem espaços extras)
A12: 1020 | B12: KM_NEGATIVO | C12: REJEITAR | D12: Quilometragem negativa | E12: Rejeitar o registro
A13: 1021 | B13: PLACA_HIFEN | C13: CORRIGIR | D13: Placa com hífen (ABC-1234) | E13: Remover o hífen
... A89: 1167 | B89: PLACA_VAZIA | C89: REJEITAR | D89: Placa não informada | E89: Rejeitar o registro e gravar o motivo na tabela de rejeitados

Sheet Resumo
A1: Indicador | B1: Valor
A2: Linhas na planilha (aba Dados) | B2: =COUNTA(Dados!A2:A168) -> 167
A3: Duplicadas a descartar | B3: =COUNTIF(Gabarito!C2:C89,"DESCARTAR") -> 6
A4: Rejeitadas (vão para a tabela de rejeitados) | B4: =COUNTIF(Gabarito!C2:C89,"REJEITAR") -> 11
A5: Linhas esperadas na FatoAtendimento | B5: =B2-B3-B4 -> 150
A6: Ocorrências de correção (classe CORRIGIR) | B6: =COUNTIF(Gabarito!C2:C89,"CORRIGIR") -> 71
A8: Tipo de problema | B8: Ocorrências | C8: Classe
A9: RESPONSAVEL_VARIANTE | B9: =COUNTIF(Gabarito!B2:B89,A9) -> 5 | C9: CORRIGIR
A10: DATA_FORMATO_ISO | B10: =COUNTIF(Gabarito!B2:B89,A10) -> 6 | C10: CORRIGIR
A11: PLACA_ESPACOS | B11: =COUNTIF(Gabarito!B2:B89,A11) -> 5 | C11: CORRIGIR
A12: DUPLICADO | B12: =COUNTIF(Gabarito!B2:B89,A12) -> 6 | C12: DESCARTAR
A13: SERVICO_VARIANTE | B13: =COUNTIF(Gabarito!B2:B89,A13) -> 25 | C13: CORRIGIR
A14: KM_VAZIO | B14: =COUNTIF(Gabarito!B2:B89,A14) -> 3 | C14: CORRIGIR
A15: PLACA_MINUSCULA | B15: =COUNTIF(Gabarito!B2:B89,A15) -> 8 | C15: CORRIGIR
A16: KM_NEGATIVO | B16: =COUNTIF(Gabarito!B2:B89,A16) -> 2 | C16: REJEITAR
A17: PLACA_HIFEN | B17: =COUNTIF(Gabarito!B2:B89,A17) -> 10 | C17: CORRIGIR
A18: STATUS_VARIANTE | B18: =COUNTIF(Gabarito!B2:B89,A18) -> 4 | C18: CORRIGIR
A19: LIBERACAO_ANTES_ENTRADA | B19: =COUNTIF(Gabarito!B2:B89,A19) -> 3 | C19: REJEITAR
A20: LIBERADO_SEM_HORARIO | B20: =COUNTIF(Gabarito!B2:B89,A20) -> 2 | C20: REJEITAR
A21: PLACA_INVALIDA | B21: =COUNTIF(Gabarito!B2:B89,A21) -> 2 | C21: REJEITAR
A22: KM_TEXTO | B22: =COUNTIF(Gabarito!B2:B89,A22) -> 2 | C22: CORRIGIR
A23: RESPONSAVEL_VAZIO | B23: =COUNTIF(Gabarito!B2:B89,A23) -> 3 | C23: CORRIGIR
A24: PLACA_VAZIA | B24: =COUNTIF(Gabarito!B2:B89,A24) -> 2 | C24: REJEITAR
